{"res": "runtime_error", "err_contains": ["ASSERTION FAILURE", "OUT OF BOUNDS", "set_to_1", "panic"]}
