{"res": "runtime_error", "err_contains": ["ASSERTION FAILURE", "OUT OF BOUNDS", "n"]}
